2025-04-22 18:52:00,760 ERROR scheduler Exception in Enqueue Events for Site erpnext.localhost
Traceback (most recent call last):
  File "/home/fandresena/Documents/Eval/Erp/apps/frappe/frappe/utils/scheduler.py", line 117, in enqueue_events_for_site
    if is_scheduler_inactive():
       ~~~~~~~~~~~~~~~~~~~~~^^
  File "/home/fandresena/Documents/Eval/Erp/apps/frappe/frappe/utils/scheduler.py", line 161, in is_scheduler_inactive
    if is_scheduler_disabled(verbose=verbose):
       ~~~~~~~~~~~~~~~~~~~~~^^^^^^^^^^^^^^^^^
  File "/home/fandresena/Documents/Eval/Erp/apps/frappe/frappe/utils/scheduler.py", line 174, in is_scheduler_disabled
    frappe.db.get_single_value("System Settings", "enable_scheduler")
    ~~~~~~~~~~~~~~~~~~~~~~~~~~^^^^^^^^^^^^^^^^^^^^^^^^^^^^^^^^^^^^^^^
  File "/home/fandresena/Documents/Eval/Erp/apps/frappe/frappe/database/database.py", line 887, in get_single_value
    df = frappe.get_meta(doctype).get_field(fieldname)
         ~~~~~~~~~~~~~~~^^^^^^^^^
  File "/home/fandresena/Documents/Eval/Erp/apps/frappe/frappe/model/meta.py", line 85, in get_meta
    meta = Meta(doctype)
  File "/home/fandresena/Documents/Eval/Erp/apps/frappe/frappe/model/meta.py", line 148, in __init__
    super().__init__("DocType", doctype)
    ~~~~~~~~~~~~~~~~^^^^^^^^^^^^^^^^^^^^
  File "/home/fandresena/Documents/Eval/Erp/apps/frappe/frappe/model/document.py", line 170, in __init__
    self._init_dispatch(args[0], *args[1:], **kwargs)
    ~~~~~~~~~~~~~~~~~~~^^^^^^^^^^^^^^^^^^^^^^^^^^^^^^
  File "/home/fandresena/Documents/Eval/Erp/apps/frappe/frappe/model/document.py", line 194, in _init_dispatch
    return self._init_known_doc(arg, name, **kwargs)
           ~~~~~~~~~~~~~~~~~~~~^^^^^^^^^^^^^^^^^^^^^
  File "/home/fandresena/Documents/Eval/Erp/apps/frappe/frappe/model/document.py", line 187, in _init_known_doc
    self.load_from_db()
    ~~~~~~~~~~~~~~~~~^^
  File "/home/fandresena/Documents/Eval/Erp/apps/frappe/frappe/model/meta.py", line 154, in load_from_db
    super().load_from_db()
    ~~~~~~~~~~~~~~~~~~~~^^
  File "/home/fandresena/Documents/Eval/Erp/apps/frappe/frappe/model/document.py", line 258, in load_from_db
    frappe.throw(
    ~~~~~~~~~~~~^
    	_("{0} {1} not found").format(_(self.doctype), self.name),
     ^^^^^^^^^^^^^^^^^^^^^^^^^^^^^^^^^^^^^^^^^^^^^^^^^^^^^^^^^^
    	frappe.DoesNotExistError(doctype=self.doctype),
     ^^^^^^^^^^^^^^^^^^^^^^^^^^^^^^^^^^^^^^^^^^^^^^^
    )
    ^
  File "/home/fandresena/Documents/Eval/Erp/apps/frappe/frappe/utils/messages.py", line 145, in throw
    msgprint(
    ~~~~~~~~^
    	msg,
     ^^^^
    ...<6 lines>...
    	primary_action=primary_action,
     ^^^^^^^^^^^^^^^^^^^^^^^^^^^^^^
    )
    ^
  File "/home/fandresena/Documents/Eval/Erp/apps/frappe/frappe/utils/messages.py", line 106, in msgprint
    _raise_exception()
    ~~~~~~~~~~~~~~~~^^
  File "/home/fandresena/Documents/Eval/Erp/apps/frappe/frappe/utils/messages.py", line 57, in _raise_exception
    raise exc
frappe.exceptions.DoesNotExistError: DocType System Settings not found
